<robot name="humanoid">

	*** Base ***
	<link 				name = "Base">
		<inertial>
			<origin 	rpy = "0.0 0.0 0.0" xyz = "0.0 0.0 0.0" />
			<mass 		value = "0.0001" />
			<inertia 	ixx = "0.0001" ixy = "0.0" ixz = "0.0" iyy = "0.0001" iyz = "0.0" izz = "0.0001" />
		</inertial>
	</link>
    
	*** pelvis ***
	<joint 				name = "Pelvis" type = "fixed">
		<parent 		link = "Base" />
		<child 			link = "Pelvis" />
		<origin 		rpy = "0.0 0.0 0.0" xyz ="0.0 0.0 0.0" />
	</joint>
	<link 				name = "Pelvis">
		<inertial>
			<origin		rpy = "0.0 0.0 0.0" xyz = "0.0 0.0 0.0" />
			<mass 		value = "9.35" />
			<inertia 	ixx = "0.1" ixy = "0.0" ixz = "0.0" iyy = "0.1" iyz = "0.0" izz = "0.1" />
		</inertial>
		<visual>
			<origin 	rpy = "0.0 1.57 0.0" xyz = "0.0 0.0 0.0" />
			<geometry>
				<cylinder length = "0.18" radius = "0.06" />
			</geometry>
        	<material 	name="Purple">
          		<color 	rgba="0.5 0.0 0.5 1.0"/>
        	</material>
      	</visual>
		<collision>
			<origin 	rpy = "0.0 1.57 0.0" xyz = "0.0 0.0 0.0" />
			<geometry>
				<cylinder length = "0.18" radius = "0.06" />
			</geometry>
		</collision>
	</link>

    *** left hip *** 
	<joint 				name = "L_Hip_rz" type = "revolute">
		<parent 		link = "Pelvis" />
		<child 			link = "L_Hip_rz" />
		<limit 			effort = "1000.0" velocity = "0.5" lower = "-0.2" upper = "0.2" />
		<origin 		rpy = "0.0 0.0 0.0" xyz = "0.1272 0.0 0.0" />
		<axis 			xyz = "0.0 0.0 1.0" />
	</joint>
	<link 				name = "L_Hip_rz">
		<inertial>
			<origin 	rpy = "0.0 0.0 0.0" xyz = "0.0 0.0 0.0" />
			<mass 		value = "1e-05" />
			<inertia 	ixx = "0.1" ixy = "0.0" ixz = "0.0" iyy = "0.1" iyz = "0.0" izz = "0.1" />
		</inertial>
		<visual>
			<origin 	rpy = "0 0 0" xyz = "0.0 0.0 0.0" />
			<geometry>
				<sphere radius = "0.04" />
			</geometry>
        	<material 	name="Yellow">
          		<color 	rgba="0.5 0.5 0.0 1.0"/>
        	</material>
      	</visual>
		<collision>
			<origin 	rpy = "0.0 0.0 0.0" xyz = "0.0 0.0 0.0" />
			<geometry>
				<sphere radius = "0.04" />
			</geometry>
		</collision>
	</link>

	<joint 				name = "L_Hip_rx" type = "revolute">
		<parent 		link = "L_Hip_rz" />
		<child 			link = "L_Hip_rx" />
		<limit 			effort = "1000.0" velocity = "0.5" lower= "-0.5" upper= "1.4" />
		<origin 		rpy = "0.0 0.0 0.0" xyz ="0.0 0.0 0.0"/>
		<axis 			xyz = "1.0 0.0 0.0" />
	</joint>
	<link 				name = "L_Hip_rx">
		<inertial>
			<origin 	rpy = "0.0 0.0 0.0" xyz = "0.0 0.0 0.0" />
			<mass 		value = "1e-05" />
			<inertia 	ixx = "0.1" ixy = "0.0" ixz = "0.0" iyy = "0.1" iyz = "0.0" izz = "0.1" />
		</inertial>
		<collision>
			<origin 	rpy = "0.0 0.0 0.0" xyz = "0.0 0.0 0.0" />
			<geometry>
				<sphere radius = "0.04" />
			</geometry>
		</collision>
	</link>
	
	<joint 				name = "L_Hip_ry" type = "revolute">
		<parent 		link = "L_Hip_rx" />
		<child 			link = "L_Hip_ry" />
		<limit 			effort = "1000.0" velocity = "0.5" lower = "-0.5" upper = "0.5" />
		<origin 		rpy = "0.0 0.0 0.0" xyz ="0.0 0.0 0.0" />
		<axis 			xyz = "0.0 1.0 0.0" />
	</joint>
	<link 				name = "L_Hip_ry">
		<inertial>
			<origin 	rpy = "0.0 0.0 0.0" xyz = "0.0 0.0 0.0" />
			<mass 		value = "1e-05" />
			<inertia 	ixx = "0.1" ixy = "0.0" ixz = "0.0" iyy = "0.1" iyz = "0.0" izz = "0.1" />
		</inertial>
		<collision>
			<origin 	rpy = "0.0 0.0 0.0" xyz = "0.0 0.0 0.0" />
			<geometry>
				<sphere radius = "0.04" />
			</geometry>
		</collision>
	</link>
	
	<joint 				name = "L_Hip_limb" type = "fixed">
		<parent 		link = "L_Hip_ry" />
		<child 			link = "L_Hip_limb" />
		<origin 		rpy = "0.0 0.0 0.0" xyz = "0.0 0.0 0.0" />
	</joint>
	<link 				name = "L_Hip_limb">
		<inertial>
			<origin 	rpy = "0.0 0.0 0.0" xyz = "0.0 -0.3 0.0" />
			<mass 		value = "7.17" />
			<inertia 	ixx = "0.1" ixy = "0.0" ixz = "0.0" iyy = "0.1" iyz = "0.0" izz = "0.1" />
		</inertial>
		<visual>
			<origin 	rpy = "1.59 0 0" xyz = "0.0 -0.22 0.0" />
			<geometry>
				<cylinder length = "0.35" radius = "0.06" />
			</geometry>
        	<material 	name="Purple">
          		<color 	rgba="0.5 0.0 0.5 1.0"/>
        	</material>
      	</visual>
		<collision>
			<origin 	rpy = "1.59 0 0" xyz = "0.0 -0.22 0.0" />
			<geometry>
				<cylinder length = "0.35" radius = "0.06" />
			</geometry>
		</collision>
	</link>

    *** left knee ***
	<joint 				name = "L_Knee_rz" type = "revolute">
		<parent 		link = "L_Hip_limb" />
		<child 			link = "L_Knee_rz" />
		<limit 			effort = "1000.0" velocity = "0.5" lower = "-0.001" upper = "0.001" />
		<origin 		rpy = "0.0 0.0 0.0" xyz = "0.0 -0.4343 0.0"/>
		<axis 			xyz = "0.0 0.0 1.0" />
	</joint>
	<link 				name = "L_Knee_rz">
		<inertial>
			<origin 	rpy = "0.0 0.0 0.0" xyz = "0.0 0.0 0.0" />
			<mass 		value = "1e-05" />
			<inertia 	ixx = "0.1" ixy = "0.0" ixz = "0.0" iyy = "0.1" iyz = "0.0" izz = "0.1" />
		</inertial>
		<visual>
			<origin 	rpy = "0 0 0" xyz = "0.0 0.0 0.0" />
			<geometry>
				<sphere radius = "0.04" />
			</geometry>
        	<material 	name="Yellow">
          		<color 	rgba="0.5 0.5 0.0 1.0"/>
        	</material>
      	</visual>
		<collision>
			<origin 	rpy = "0.0 0.0 0.0" xyz = "0.0 0.0 0.0" />
			<geometry>
				<sphere radius = "0.05" />
			</geometry>
		</collision>
	</link>

    <joint 				name = "L_Knee_rx" type = "revolute">
		<parent 		link = "L_Knee_rz" />
		<child 			link = "L_Knee_rx" />
		<limit 			effort = "1000.0" velocity = "0.5" lower = "-0.001" upper = "2.5" />
		<origin 		rpy = "0.0 0.0 0.0" xyz ="0.0 0.0 0.0"/>
		<axis 			xyz = "1.0 0.0 0.0" />
	</joint>
	<link 				name = "L_Knee_rx">
		<inertial>
			<origin 	rpy = "0.0 0.0 0.0" xyz = "0.0 0.0 0.0" />
			<mass 		value = "1e-05" />
			<inertia 	ixx = "0.1" ixy = "0.0" ixz = "0.0" iyy = "0.1" iyz = "0.0" izz = "0.1" />
		</inertial>
		<collision>
			<origin 	rpy = "0.0 0.0 0.0" xyz = "0.0 0.0 0.0" />
			<geometry>
				<sphere radius = "0.05" />
			</geometry>
		</collision>
	</link>

    <joint 				name = "L_Knee_ry" type = "revolute">
		<parent 		link = "L_Knee_rx" />
		<child 			link = "L_Knee_ry" />
		<limit 			effort = "1000.0" velocity = "0.5" lower = "-0.001" upper = "0.001"/>
		<origin 		rpy = "0 0 0" xyz = "0.0 0.0 0.0"/>
		<axis 			xyz = "0.0 1.0 0.0" />
	</joint>
	<link 				name = "L_Knee_ry">
		<inertial>
			<origin 	rpy = "0.0 0.0 0.0"  xyz = "0.0 0.0 0.0" />
			<mass 		value = "1e-05" />
			<inertia 	ixx = "0.1" ixy = "0.0" ixz = "0.0" iyy = "0.1" iyz = "0.0" izz = "0.1" />
		</inertial>
		<collision>
			<origin 	rpy = "0.0 0.0 0.0"  xyz = "0.0 0.0 0.0" />
			<geometry>
				<sphere radius = "0.05" />
			</geometry>
		</collision>
	</link>

	<joint 				name = "L_Knee_limb" type = "fixed">
		<parent 		link = "L_Knee_ry" />
		<child 			link = "L_Knee_limb" />
		<origin 		rpy = "0.0 0.0 0.0" xyz = "0.0 0.0 0.0"  />
	</joint>
	<link 				name = "L_Knee_limb">
		<inertial>
			<origin 	rpy = "0.0 0.0 0.0"  xyz = "0.0 -0.1 0.0" />
			<mass 		value = "3.25" />
			<inertia 	ixx = "0.1" ixy = "0.0" ixz = "0.0" iyy = "0.1" iyz = "0.0" izz = "0.1" />
		</inertial>
		<visual>
			<origin 	rpy = "1.57 0 0"  xyz = "0.0 -0.22 0.0" />
			<geometry>
				<cylinder length = "0.37" radius = "0.06" />
			</geometry>
        	<material 	name="Purple">
          		<color 	rgba="0.5 0.0 0.5 1.0"/>
        	</material>
      	</visual>
		<collision>
			<origin 	rpy = "1.57 0 0"  xyz = "0.0 -0.22 0.0" />
			<geometry>
				<cylinder length = "0.37" radius = "0.06" />
			</geometry>
		</collision>
	</link>
	
	*** left ankle ***
	<joint 				name = "L_Ankle_rz" type = "revolute">
		<parent 		link = "L_Knee_limb" />
		<child 			link = "L_Ankle_rz" />
		<limit 			effort = "1000.0" velocity = "0.5" lower = "-0.005" upper = "0.005" />
		<origin 		rpy = "0.0 0.0 0.0" xyz = "0.0 -0.4487 0.0" />
		<axis 			xyz = "0.0 0.0 1.0" />
	</joint>
	<link 				name = "L_Ankle_rz">
		<inertial>
			<origin 	rpy = "0.0 0.0 0.0" xyz = "0.0 0.0 0.0" />
			<mass 		value = "1e-05" />
			<inertia 	ixx = "0.1" ixy = "0.0" ixz = "0.0" iyy = "0.1" iyz = "0.0" izz = "0.1" />
		</inertial>
		<collision>
			<origin 	rpy = "0.0 0.0 0.0" xyz = "0.0 0.0 0.0" />
			<geometry>
				<sphere radius = "0.03" />
			</geometry>
		</collision>
	</link>

	<joint 				name = "L_Ankle_rx" type = "revolute">
		<parent 		link = "L_Ankle_rz" />
		<child 			link = "L_Ankle_rx" />
		<limit 			effort = "1000.0" velocity = "0.5" lower = "-0.005" upper = "0.2" />
		<origin 		rpy = "0.0 0.0 0.0" xyz = "0.0 0.0 0.0"/>
		<axis 			xyz = "1.0 0.0 0.0" />
	</joint>
	<link 				name = "L_Ankle_rx">
		<inertial>
			<origin 	rpy = "0.0 0.0 0.0" xyz = "0.0 0.0 0.0" />
			<mass 		value = "1e-05" />
			<inertia 	ixx = "0.1" ixy = "0.0" ixz = "0.0" iyy = "0.1" iyz = "0.0" izz = "0.1" />
		</inertial>
		<collision>
			<origin 	rpy = "0.0 0.0 0.0" xyz = "0.0 0.0 0.0" />
			<geometry>
				<sphere radius = "0.03" />
			</geometry>
		</collision>
	</link>
	
	<joint 				name = "L_Ankle_ry" type = "revolute">
		<parent 		link = "L_Ankle_rx" />
		<child 			link = "L_Ankle_ry" />
		<limit 			effort = "1000.0" velocity = "0.5" lower = "-0.005" upper = "0.005" />
		<origin 		rpy = "0.0 0.0 0.0" xyz = "0.0 0.0 0.0"  />
		<axis 			xyz = "0.0 1.0 0.0" />
	</joint>
	<link 				name = "L_Ankle_ry">
		<inertial>
			<origin 	rpy = "0.0 0.0 0.0" xyz = "0.0 0.0 0.0" />
			<mass 		value = "1e-05" />
			<inertia 	ixx = "0.1" ixy = "0.0" ixz = "0.0" iyy = "0.1" iyz = "0.0" izz = "0.1" />
		</inertial>
		<collision>
			<origin 	rpy = "0.0 0.0 0.0" xyz = "0.0 0.0 0.0" />
			<geometry>
				<sphere radius = "0.03" />
			</geometry>
		</collision>
	</link>

	<joint 				name = "L_Ankle_limb" type = "fixed">
		<parent 		link = "L_Ankle_ry" />
		<child 			link = "L_Ankle_limb" />
		<origin 		rpy = "0.0 0.0 0.0" xyz = "0.0 0.0 0.0"  />
	</joint>
	<link 				name = "L_Ankle_limb">
		<inertial>
			<origin 	rpy = "0.0 0.0 0.0" xyz = "0.0 -0.015 0.04" />
			<mass 		value = "0.93" />
			<inertia 	ixx = "0.1" ixy = "0.0" ixz = "0.0" iyy = "0.1" iyz = "0.0" izz = "0.1" />
		</inertial>
		<visual>
			<origin 	rpy = "0.0 0.0 0.0" xyz = "0.0 -0.015 0.06" />
			<geometry>
				<box 	size = "0.08 0.03 0.18" />
			</geometry>
        	<material 	name="Purple">
          		<color 	rgba="0.5 0.0 0.5 1.0"/>
        	</material>
      	</visual>
		<collision>
			<origin 	rpy = "0.0 0.0 0.0" xyz = "0.0 -0.015 0.06" />
			<geometry>
				<box 	size = "0.08 0.03 0.18" />
			</geometry>
		</collision>
	</link>
	
	*** left foot ***
	<joint 				name = "L_Foot_rz" type = "revolute">
		<parent 		link = "L_Ankle_limb" />
		<child 			link = "L_Foot_rz" />
		<limit 			effort = "1000.0" velocity="0.5" lower = "-0.001" upper = "0.001" />
		<origin 		rpy = "0 0 0" xyz = "0.0 0.0 0.1515"/>
		<axis 			xyz = "0.0 0.0 1.0" />
	</joint>
	<link 				name = "L_Foot_rz">
		<inertial>
			<origin 	rpy = "0.0 0.0 0.0"  xyz = "0.0 0.0 0.0" />
			<mass 		value = "1e-05" />
			<inertia 	ixx = "0.1" ixy = "0.0" ixz = "0.0" iyy = "0.1" iyz = "0.0" izz = "0.1" />
		</inertial>
		<collision>
			<origin 	rpy = "0.0 0.0 0.0"  xyz = "0.0 0.0 0.0" />
			<geometry>
				<sphere radius = "0.01" />
			</geometry>
		</collision>
	</link>

    <joint 				name = "L_Foot_rx" type = "revolute">
		<parent 		link = "L_Foot_rz" />
		<child 			link = "L_Foot_rx" />
		<limit 			effort = "1000.0" velocity = "0.5" lower = "-0.001" upper = "0.2" />
		<origin 		rpy = "0.0 0.0 0.0" xyz = "0.0 0.0 0.0" />
		<axis 			xyz = "1.0 0.0 0.0" />
	</joint>
	<link 				name = "L_Foot_rx">
		<inertial>
			<origin 	rpy = "0.0 0.0 0.0"  xyz = "0.0 0.0 0.0" />
			<mass 		value = "1e-05" />
			<inertia 	ixx = "0.1" ixy = "0.0" ixz = "0.0" iyy = "0.1" iyz = "0.0" izz = "0.1" />
		</inertial>
		<collision>
			<origin 	rpy = "0.0 0.0 0.0"  xyz = "0.0 0.0 0.0" />
			<geometry>
				<sphere radius = "0.01" />
			</geometry>
		</collision>
	</link>

    <joint 				name = "L_Foot_ry" type = "revolute">
		<parent 		link = "L_Foot_rx" />
		<child 			link = "L_Foot_ry" />
		<limit 			effort = "1000.0" velocity = "0.5" lower= "-0.001" upper= "0.001" />
		<origin			rpy = "0.0 0.0 0.0" xyz ="0.0 0.0 0.0"/>
		<axis 			xyz = "0.0 1.0 0.0" />
	</joint>
	<link 				name = "L_Foot_ry">
		<inertial>
			<origin 	rpy = "0.0 0.0 0.0"  xyz = "0.0 0.0 0.0" />
			<mass 		value = "0.01" />
			<inertia 	ixx = "0.1" ixy = "0.0" ixz = "0.0" iyy = "0.1" iyz = "0.0" izz = "0.1" />
		</inertial>
		<collision>
			<origin 	rpy = "0.0 1.57 0.0"  xyz = "0.0 0.0 0.0" />
			<geometry>
				<cylinder length = "0.08" radius = "0.01"  />
			</geometry>
		</collision>
	</link>
	
	*** left leg end***
	<joint 				name = "L_Lend" type = "fixed">
		<parent 		link = "L_Foot_ry" />
		<child 			link = "L_Lend" />
		<origin 		rpy = "0.0 0.0 0.0" xyz = "0.0 0.0 0.0750" />
	</joint>
	<link 				name = "L_Lend">
		<inertial>
			<origin 	rpy = "0.0 0.0 0.0" xyz = "0.0 0.0 0.0" />
			<mass 		value = "0.01" />
			<inertia 	ixx = "0.1" ixy = "0.0" ixz = "0.0" iyy = "0.1" iyz = "0.0" izz = "0.1" />
		</inertial>
		<visual>
			<origin 	rpy = "0.0 0.0 0.0" xyz = "0.0 -0.015 -0.02" />
			<geometry>
				<box 	size = "0.08 0.03 0.08" />
			</geometry>
        	<material 	name="Purple">
          		<color 	rgba="0.5 0.0 0.5 1.0"/>
        	</material>
      	</visual>
		<collision>
			<origin 	rpy = "0.0 0.0 0.0" xyz = "0.0 -0.015 -0.02" />
			<geometry>
				<box 	size = "0.08 0.03 0.08" />
			</geometry>
		</collision>
	</link>

    *** right hip ***
	<joint 				name = "R_Hip_rz" type = "revolute">
		<parent 		link = "Pelvis" />
		<child 			link = "R_Hip_rz" />
		<limit 			effort = "1000.0" velocity = "0.5" lower = "-0.2" upper = "0.2" />
		<origin 		rpy = "0.0 0.0 0.0" xyz = "-0.1272 0.0 0.0" />
		<axis 			xyz = "0.0 0.0 1.0" />
	</joint>
	<link 				name = "R_Hip_rz">
		<inertial>
			<origin 	rpy = "0.0 0.0 0.0" xyz = "0.0 0.0 0.0" />
			<mass 		value = "1e-05" />
			<inertia 	ixx = "0.1" ixy = "0.0" ixz = "0.0" iyy = "0.1" iyz = "0.0" izz = "0.1" />
		</inertial>
		<visual>
			<origin 	rpy = "0 0 0" xyz = "0.0 0.0 0.0" />
			<geometry>
				<sphere radius = "0.04" />
			</geometry>
        	<material 	name="Yellow">
          		<color 	rgba="0.5 0.5 0.0 1.0"/>
        	</material>
      	</visual>
		<collision>
			<origin 	rpy = "0.0 0.0 0.0" xyz = "0.0 0.0 0.0" />
			<geometry>
				<sphere radius = "0.04" />
			</geometry>
		</collision>
	</link>

	<joint 				name = "R_Hip_rx" type = "revolute">
		<parent 		link = "R_Hip_rz" />
		<child 			link = "R_Hip_rx" />
		<limit 			effort = "1000.0" velocity = "0.5" lower= "-0.5" upper= "1.4" />
		<origin 		rpy = "0.0 0.0 0.0" xyz ="0.0 0.0 0.0"/>
		<axis 			xyz = "1.0 0.0 0.0" />
	</joint>
	<link 				name = "R_Hip_rx">
		<inertial>
			<origin 	rpy = "0.0 0.0 0.0" xyz = "0.0 0.0 0.0" />
			<mass 		value = "1e-05" />
			<inertia 	ixx = "0.1" ixy = "0.0" ixz = "0.0" iyy = "0.1" iyz = "0.0" izz = "0.1" />
		</inertial>
		<collision>
			<origin 	rpy = "0.0 0.0 0.0" xyz = "0.0 0.0 0.0" />
			<geometry>
				<sphere radius = "0.04" />
			</geometry>
		</collision>
	</link>
	
	<joint 				name = "R_Hip_ry" type = "revolute">
		<parent 		link = "R_Hip_rx" />
		<child 			link = "R_Hip_ry" />
		<limit 			effort = "1000.0" velocity = "0.5" lower = "-0.5" upper = "0.5" />
		<origin 		rpy = "0.0 0.0 0.0" xyz ="0.0 0.0 0.0" />
		<axis 			xyz = "0.0 1.0 0.0" />
	</joint>
	<link 				name = "R_Hip_ry">
		<inertial>
			<origin 	rpy = "0.0 0.0 0.0" xyz = "0.0 0.0 0.0" />
			<mass 		value = "1e-05" />
			<inertia 	ixx = "0.1" ixy = "0.0" ixz = "0.0" iyy = "0.1" iyz = "0.0" izz = "0.1" />
		</inertial>
		<collision>
			<origin 	rpy = "0.0 0.0 0.0" xyz = "0.0 0.0 0.0" />
			<geometry>
				<sphere radius = "0.04" />
			</geometry>
		</collision>
	</link>
	
	<joint 				name = "R_Hip_limb" type = "fixed">
		<parent 		link = "R_Hip_ry" />
		<child 			link = "R_Hip_limb" />
		<origin 		rpy = "0.0 0.0 0.0" xyz = "0.0 0.0 0.0" />
	</joint>
	<link 				name = "R_Hip_limb">
		<inertial>
			<origin 	rpy = "0.0 0.0 0.0" xyz = "0.0 -0.3 0.0" />
			<mass 		value = "7.17" />
			<inertia 	ixx = "0.1" ixy = "0.0" ixz = "0.0" iyy = "0.1" iyz = "0.0" izz = "0.1" />
		</inertial>
		<visual>
			<origin 	rpy = "1.59 0 0" xyz = "0.0 -0.22 0.0" />
			<geometry>
				<cylinder length = "0.35" radius = "0.06" />
			</geometry>
        	<material 	name="Purple">
          		<color 	rgba="0.5 0.0 0.5 1.0"/>
        	</material>
      	</visual>
		<collision>
			<origin 	rpy = "1.59 0 0" xyz = "0.0 -0.22 0.0" />
			<geometry>
				<cylinder length = "0.35" radius = "0.06" />
			</geometry>
		</collision>
	</link>
	
	*** right knee ***
    <joint 				name = "R_Knee_rz" type = "revolute">
		<parent 		link = "R_Hip_limb" />
		<child 			link = "R_Knee_rz" />
		<limit 			effort = "1000.0" velocity = "0.5" lower = "-0.001" upper = "0.001" />
		<origin 		rpy = "0.0 0.0 0.0" xyz = "0.0 -0.4343 0.0"/>
		<axis 			xyz = "0.0 0.0 1.0" />
	</joint>
	<link 				name = "R_Knee_rz">
		<inertial>
			<origin 	rpy = "0.0 0.0 0.0" xyz = "0.0 0.0 0.0" />
			<mass 		value = "1e-05" />
			<inertia 	ixx = "0.1" ixy = "0.0" ixz = "0.0" iyy = "0.1" iyz = "0.0" izz = "0.1" />
		</inertial>
		<visual>
			<origin 	rpy = "0 0 0" xyz = "0.0 0.0 0.0" />
			<geometry>
				<sphere radius = "0.04" />
			</geometry>
        	<material 	name="Yellow">
          		<color 	rgba="0.5 0.5 0.0 1.0"/>
        	</material>
      	</visual>
		<collision>
			<origin 	rpy = "0.0 0.0 0.0" xyz = "0.0 0.0 0.0" />
			<geometry>
				<sphere radius = "0.05" />
			</geometry>
		</collision>
	</link>

    <joint 				name = "R_Knee_rx" type = "revolute">
		<parent 		link = "R_Knee_rz" />
		<child 			link = "R_Knee_rx" />
		<limit 			effort = "1000.0" velocity = "0.5" lower = "-0.001" upper = "2.5" />
		<origin 		rpy = "0.0 0.0 0.0" xyz ="0.0 0.0 0.0"/>
		<axis 			xyz = "1.0 0.0 0.0" />
	</joint>
	<link 				name = "R_Knee_rx">
		<inertial>
			<origin 	rpy = "0.0 0.0 0.0" xyz = "0.0 0.0 0.0" />
			<mass 		value = "1e-05" />
			<inertia 	ixx = "0.1" ixy = "0.0" ixz = "0.0" iyy = "0.1" iyz = "0.0" izz = "0.1" />
		</inertial>
		<collision>
			<origin 	rpy = "0.0 0.0 0.0" xyz = "0.0 0.0 0.0" />
			<geometry>
				<sphere radius = "0.05" />
			</geometry>
		</collision>
	</link>

    <joint 				name = "R_Knee_ry" type = "revolute">
		<parent 		link = "R_Knee_rx" />
		<child 			link = "R_Knee_ry" />
		<limit 			effort = "1000.0" velocity = "0.5" lower = "-0.001" upper = "0.001"/>
		<origin 		rpy = "0 0 0" xyz = "0.0 0.0 0.0"/>
		<axis 			xyz = "0.0 1.0 0.0" />
	</joint>
	<link 				name = "R_Knee_ry">
		<inertial>
			<origin 	rpy = "0.0 0.0 0.0"  xyz = "0.0 0.0 0.0" />
			<mass 		value = "1e-05" />
			<inertia 	ixx = "0.1" ixy = "0.0" ixz = "0.0" iyy = "0.1" iyz = "0.0" izz = "0.1" />
		</inertial>
		<collision>
			<origin 	rpy = "0.0 0.0 0.0"  xyz = "0.0 0.0 0.0" />
			<geometry>
				<sphere radius = "0.05" />
			</geometry>
		</collision>
	</link>

	<joint 				name = "R_Knee_limb" type = "fixed">
		<parent 		link = "R_Knee_ry" />
		<child 			link = "R_Knee_limb" />
		<origin 		rpy = "0.0 0.0 0.0" xyz = "0.0 0.0 0.0"  />
	</joint>
	<link 				name = "R_Knee_limb">
		<inertial>
			<origin 	rpy = "0.0 0.0 0.0"  xyz = "0.0 -0.1 0.0" />
			<mass 		value = "3.25" />
			<inertia 	ixx = "0.1" ixy = "0.0" ixz = "0.0" iyy = "0.1" iyz = "0.0" izz = "0.1" />
		</inertial>
		<visual>
			<origin 	rpy = "1.57 0 0"  xyz = "0.0 -0.22 0.0" />
			<geometry>
				<cylinder length = "0.37" radius = "0.06" />
			</geometry>
        	<material 	name="Purple">
          		<color 	rgba="0.5 0.0 0.5 1.0"/>
        	</material>
      	</visual>
		<collision>
			<origin 	rpy = "1.57 0 0"  xyz = "0.0 -0.22 0.0" />
			<geometry>
				<cylinder length = "0.37" radius = "0.06" />
			</geometry>
		</collision>
	</link>
	
	*** right ankle ***
	<joint 				name = "R_Ankle_rz" type = "revolute">
		<parent 		link = "R_Knee_limb" />
		<child 			link = "R_Ankle_rz" />
		<limit 			effort = "1000.0" velocity = "0.5" lower = "-0.005" upper = "0.005" />
		<origin 		rpy = "0.0 0.0 0.0" xyz = "0.0 -0.4487 0.0" />
		<axis 			xyz = "0.0 0.0 1.0" />
	</joint>
	<link 				name = "R_Ankle_rz">
		<inertial>
			<origin 	rpy = "0.0 0.0 0.0" xyz = "0.0 0.0 0.0" />
			<mass 		value = "1e-05" />
			<inertia 	ixx = "0.1" ixy = "0.0" ixz = "0.0" iyy = "0.1" iyz = "0.0" izz = "0.1" />
		</inertial>
		<collision>
			<origin 	rpy = "0.0 0.0 0.0" xyz = "0.0 0.0 0.0" />
			<geometry>
				<sphere radius = "0.03" />
			</geometry>
		</collision>
	</link>

	<joint 				name = "R_Ankle_rx" type = "revolute">
		<parent 		link = "R_Ankle_rz" />
		<child 			link = "R_Ankle_rx" />
		<limit 			effort = "1000.0" velocity = "0.5" lower = "-0.005" upper = "0.2" />
		<origin 		rpy = "0.0 0.0 0.0" xyz = "0.0 0.0 0.0"/>
		<axis 			xyz = "1.0 0.0 0.0" />
	</joint>
	<link 				name = "R_Ankle_rx">
		<inertial>
			<origin 	rpy = "0.0 0.0 0.0" xyz = "0.0 0.0 0.0" />
			<mass 		value = "1e-05" />
			<inertia 	ixx = "0.1" ixy = "0.0" ixz = "0.0" iyy = "0.1" iyz = "0.0" izz = "0.1" />
		</inertial>
		<collision>
			<origin 	rpy = "0.0 0.0 0.0" xyz = "0.0 0.0 0.0" />
			<geometry>
				<sphere radius = "0.03" />
			</geometry>
		</collision>
	</link>
	
	<joint 				name = "R_Ankle_ry" type = "revolute">
		<parent 		link = "R_Ankle_rx" />
		<child 			link = "R_Ankle_ry" />
		<limit 			effort = "1000.0" velocity = "0.5" lower = "-0.005" upper = "0.005" />
		<origin 		rpy = "0.0 0.0 0.0" xyz = "0.0 0.0 0.0"  />
		<axis 			xyz = "0.0 1.0 0.0" />
	</joint>
	<link 				name = "R_Ankle_ry">
		<inertial>
			<origin 	rpy = "0.0 0.0 0.0" xyz = "0.0 0.0 0.0" />
			<mass 		value = "1e-05" />
			<inertia 	ixx = "0.1" ixy = "0.0" ixz = "0.0" iyy = "0.1" iyz = "0.0" izz = "0.1" />
		</inertial>
		<collision>
			<origin 	rpy = "0.0 0.0 0.0" xyz = "0.0 0.0 0.0" />
			<geometry>
				<sphere radius = "0.03" />
			</geometry>
		</collision>
	</link>

	<joint 				name = "R_Ankle_limb" type = "fixed">
		<parent 		link = "R_Ankle_ry" />
		<child 			link = "R_Ankle_limb" />
		<origin 		rpy = "0.0 0.0 0.0" xyz = "0.0 0.0 0.0"  />
	</joint>
	<link 				name = "R_Ankle_limb">
		<inertial>
			<origin 	rpy = "0.0 0.0 0.0" xyz = "0.0 -0.015 0.04" />
			<mass 		value = "0.93" />
			<inertia 	ixx = "0.1" ixy = "0.0" ixz = "0.0" iyy = "0.1" iyz = "0.0" izz = "0.1" />
		</inertial>
		<visual>
			<origin 	rpy = "0.0 0.0 0.0" xyz = "0.0 -0.015 0.06" />
			<geometry>
				<box 	size = "0.08 0.03 0.18" />
			</geometry>
        	<material 	name="Purple">
          		<color 	rgba="0.5 0.0 0.5 1.0"/>
        	</material>
      	</visual>
		<collision>
			<origin 	rpy = "0.0 0.0 0.0" xyz = "0.0 -0.015 0.06" />
			<geometry>
				<box 	size = "0.08 0.03 0.18" />
			</geometry>
		</collision>
	</link>
	
	*** right foot ***
    <joint 				name = "R_Foot_rz" type = "revolute">
		<parent 		link = "R_Ankle_limb" />
		<child 			link = "R_Foot_rz" />
		<limit 			effort = "1000.0" velocity = "0.5" lower = "-0.001" upper = "0.001" />
		<origin 		rpy = "0 0 0" xyz = "0.0 0.0 0.1515"/>
		<axis 			xyz = "0.0 0.0 1.0" />
	</joint>
	<link 				name = "R_Foot_rz">
		<inertial>
			<origin 	rpy = "0.0 0.0 0.0"  xyz = "0.0 0.0 0.0" />
			<mass 		value = "1e-05" />
			<inertia 	ixx = "0.1" ixy = "0.0" ixz = "0.0" iyy = "0.1" iyz = "0.0" izz = "0.1" />
		</inertial>
		<collision>
			<origin 	rpy = "0.0 0.0 0.0"  xyz = "0.0 0.0 0.0" />
			<geometry>
				<sphere radius = "0.01" />
			</geometry>
		</collision>
	</link>

    <joint 				name = "R_Foot_rx" type = "revolute">
		<parent 		link = "R_Foot_rz" />
		<child 			link = "R_Foot_rx" />
		<limit 			effort = "1000.0" velocity = "0.5" lower = "-0.001" upper = "0.2" />
		<origin 		rpy = "0.0 0.0 0.0" xyz = "0.0 0.0 0.0" />
		<axis 			xyz = "1.0 0.0 0.0" />
	</joint>
	<link 				name = "R_Foot_rx">
		<inertial>
			<origin 	rpy = "0.0 0.0 0.0"  xyz = "0.0 0.0 0.0" />
			<mass 		value = "1e-05" />
			<inertia 	ixx = "0.1" ixy = "0.0" ixz = "0.0" iyy = "0.1" iyz = "0.0" izz = "0.1" />
		</inertial>
		<collision>
			<origin 	rpy = "0.0 0.0 0.0"  xyz = "0.0 0.0 0.0" />
			<geometry>
				<sphere radius = "0.01" />
			</geometry>
		</collision>
	</link>

    <joint 				name = "R_Foot_ry" type = "revolute">
		<parent 		link = "R_Foot_rx" />
		<child 			link = "R_Foot_ry" />
		<limit 			effort = "1000.0" velocity = "0.5" lower= "-0.001" upper= "0.001" />
		<origin			rpy = "0.0 0.0 0.0" xyz ="0.0 0.0 0.0"/>
		<axis 			xyz = "0.0 1.0 0.0" />
	</joint>
	<link 				name = "R_Foot_ry">
		<inertial>
			<origin 	rpy = "0.0 0.0 0.0"  xyz = "0.0 0.0 0.0" />
			<mass 		value = "0.01" />
			<inertia 	ixx = "0.1" ixy = "0.0" ixz = "0.0" iyy = "0.1" iyz = "0.0" izz = "0.1" />
		</inertial>
		<collision>
			<origin 	rpy = "0.0 1.57 0.0"  xyz = "0.0 0.0 0.0" />
			<geometry>
				<cylinder length = "0.08" radius = "0.01"  />
			</geometry>
		</collision>
	</link>
	
	*** right leg end ***
	<joint 				name = "R_Rend" type = "fixed">
		<parent 		link = "R_Foot_ry" />
		<child 			link = "R_Rend" />
		<origin 		rpy = "0.0 0.0 0.0" xyz = "0.0 0.0 0.0750" />
	</joint>
	<link 				name = "R_Rend">
		<inertial>
			<origin 	rpy = "0.0 0.0 0.0" xyz = "0.0 0.0 0.0" />
			<mass 		value = "0.01" />
			<inertia 	ixx = "0.1" ixy = "0.0" ixz = "0.0" iyy = "0.1" iyz = "0.0" izz = "0.1" />
		</inertial>
		<visual>
			<origin 	rpy = "0.0 0.0 0.0" xyz = "0.0 -0.015 -0.02" />
			<geometry>
				<box 	size = "0.08 0.03 0.08" />
			</geometry>
        	<material 	name="Purple">
          		<color 	rgba="0.5 0.0 0.5 1.0"/>
        	</material>
      	</visual>
		<collision>
			<origin 	rpy = "0.0 0.0 0.0" xyz = "0.0 -0.015 -0.02" />
			<geometry>
				<box 	size = "0.08 0.03 0.08" />
			</geometry>
		</collision>
	</link>

    *** spine 1 ***
	<joint 				name = "spine1_rz" type = "revolute">
		<parent 		link = "Pelvis" />
		<child 			link = "spine1_rz" />
		<limit 			effort = "100.0" velocity = "0.5" lower = "-0.001" upper = "0.001" />
		<origin 		rpy = "0.0 0.0 0.0" xyz = "0.0 0.001 0.0" />
		<axis 			xyz = "0.0 0.0 1.0" />
	</joint>
	<link 				name = "spine1_rz">
		<inertial>
			<origin 	rpy = "0.0 0.0 0.0" xyz = "0.0 0.0 0.0" />
			<mass 		value = "1e-05" />
			<inertia 	ixx = "0.1" ixy = "0.0" ixz = "0.0" iyy = "0.1" iyz = "0.0" izz = "0.1" />
		</inertial>
		<collision>
			<origin 	rpy = "0.0 0.0 0.0" xyz = "0.0 0.0 0.0" />
			<geometry>
				<sphere radius = "0.04" />
			</geometry>
		</collision>
	</link>

	<joint 				name="spine1_rx" type = "revolute">
		<parent 		link = "spine1_rz" />
		<child 			link = "spine1_rx" />
		<limit 			effort = "100.0" velocity = "0.5" lower = "-0.001" upper = "0.001" />
		<origin 		rpy = "0.0 0.0 0.0" xyz = "0.0 0.0 0.0"/>
		<axis 			xyz = "1.0 0.0 0.0" />
	</joint>
	<link 				name = "spine1_rx">
		<inertial>
			<origin 	rpy = "0.0 0.0 0.0" xyz = "0.0 0.0 0.0" />
			<mass 		value = "1e-05" />
			<inertia 	ixx = "0.1" ixy = "0.0" ixz = "0.0" iyy = "0.1" iyz = "0.0" izz = "0.1" />
		</inertial>
		<collision>
			<origin 	rpy = "0.0 0.0 0.0" xyz = "0.0 0.0 0.0" />
			<geometry>
				<sphere radius = "0.04" />
			</geometry>
		</collision>
	</link>
	
	<joint 				name = "spine1_ry" type = "revolute">
		<parent 		link = "spine1_rx" />
		<child 			link = "spine1_ry" />
		<limit 			effort = "100.0" velocity = "0.5" lower = "-0.1" upper = "0.1" />
		<origin 		rpy = "0.0 0.0 0.0" xyz = "0.0 0.0 0.0"  />
		<axis 			xyz = "0.0 1.0 0.0" />
	</joint>
	<link 				name = "spine1_ry">
		<inertial>
			<origin 	rpy = "0.0 0.0 0.0" xyz = "0.0 0.0 0.0" />
			<mass 		value = "1e-05" />
			<inertia 	ixx = "0.1" ixy = "0" ixz = "0" iyy = "0.1" iyz = "0" izz = "0.1" />
		</inertial>
		<collision>
			<origin 	rpy = "0.0 0.0 0.0" xyz = "0.0 0.0 0.0" />
			<geometry>
				<sphere radius = "0.04" />
			</geometry>
		</collision>
	</link>

	<joint 				name="spine1_limb" type="fixed">
		<parent 		link = "spine1_ry" />
		<child 			link = "spine1_limb" />
		<origin 		rpy = "0.0 0.0 0.0" xyz = "0.0 0.0 0.0"  />
	</joint>
	<link 				name = "spine1_limb">
		<inertial>
			<origin 	rpy = "0.0 0.0 0.0" xyz = "0.0 0.12 0.0" />
			<mass 		value = "0.1" />
			<inertia 	ixx = "0.1" ixy = "0.0" ixz = "0.0" iyy = "0.1" iyz = "0.0" izz = "0.1" />
		</inertial>
		<visual>
			<origin 	rpy = "0.0 1.57 0.0" xyz = "0.0 0.12 0.0" />
			<geometry>
				<cylinder length = "0.22" radius = "0.05" />
			</geometry>
        	<material 	name="Purple">
          		<color 	rgba="0.5 0.0 0.5 1.0"/>
        	</material>
      	</visual>
		<collision>
			<origin 	rpy = "0.0 1.57 0.0" xyz = "0.0 0.12 0.0" />
			<geometry>
				<cylinder length = "0.22" radius = "0.05" />
			</geometry>
		</collision>
	</link>

    *** spine 2 ***
	<joint 				name = "spine2_rz" type = "revolute">
		<parent 		link = "spine1_limb" />
		<child 			link = "spine2_rz" />
		<limit 			effort = "100.0" velocity = "0.5" lower = "-0.1" upper = "0.1" />
		<origin 		rpy = "0.0 0.0 0.0" xyz = "0.0 0.2459 0.0"  />
		<axis 			xyz = "0.0 0.0 1.0" />
	</joint>
	<link 				name = "spine2_rz">
		<inertial>
			<origin 	rpy = "0.0 0.0 0.0" xyz = "0.0 0.0 0.0" />
			<mass 		value = "1e-05" />
			<inertia 	ixx = "0.1" ixy = "0" ixz = "0" iyy = "0.1" iyz = "0" izz = "0.1" />
		</inertial>
		<visual>
			<origin 	rpy = "0 0 0" xyz = "0.0 0.0 0.0" />
			<geometry>
				<sphere radius = "0.04" />
			</geometry>
        	<material 	name="Yellow">
          		<color 	rgba="0.5 0.5 0.0 1.0"/>
        	</material>
      	</visual>
		<collision>
			<origin 	rpy = "0.0 0.0 0.0" xyz = "0.0 0.0 0.0" />
			<geometry>
				<sphere radius = "0.04" />
			</geometry>
		</collision>
	</link>

	<joint 				name = "spine2_rx" type = "revolute">
		<parent 		link = "spine2_rz" />
		<child 			link = "spine2_rx" />
		<limit 			effort = "100.0" velocity = "0.5" lower = "-0.05" upper = "1.0" />
		<origin 		rpy = "0.0 0.0 0.0" xyz = "0.0 0.0 0.0"/>
		<axis 			xyz = "1.0 0.0 0.0" />
	</joint>
	<link 				name = "spine2_rx">
		<inertial>
			<origin 	rpy = "0.0 0.0 0.0" xyz = "0.0 0.0 0.0" />
			<mass 		value = "1e-05" />
			<inertia 	ixx = "0.1" ixy = "0.0" ixz = "0.0" iyy = "0.1" iyz = "0.0" izz = "0.1" />
		</inertial>
		<collision>
			<origin 	rpy = "0.0 0.0 0.0" xyz = "0.0 0.0 0.0" />
			<geometry>
				<sphere radius = "0.04" />
			</geometry>
		</collision>
	</link>
	
	<joint 				name = "spine2_ry" type = "revolute">
		<parent 		link = "spine2_rx" />
		<child 			link = "spine2_ry" />
		<limit 			effort = "100.0" velocity = "0.5" lower = "-0.1" upper = "0.1" />
		<origin 		rpy = "0 0 0" xyz = "0.0 0.0 0.0"  />
		<axis 			xyz = "0.0 1.0 0.0" />
	</joint>
	<link 				name = "spine2_ry">
		<inertial>
			<origin 	rpy = "0.0 0.0 0.0"  xyz = "0.0 0.0 0.0" />
			<mass 		value = "1e-05" />
			<inertia 	ixx = "0.1" ixy = "0.0" ixz = "0.0" iyy = "0.1" iyz = "0.0" izz = "0.1" />
		</inertial>
		<collision>
			<origin 	rpy = "0.0 0.0 0.0"  xyz = "0.0 0.0 0.0" />
			<geometry>
				<sphere radius = "0.04" />
			</geometry>
		</collision>
	</link>

	<joint 				name = "spine2_limb" type = "fixed">
		<parent 		link = "spine2_ry" />
		<child 			link = "spine2_limb" />
		<origin 		rpy = "0.0 0.0 0.0" xyz = "0.0 0.0 0.0"  />
	</joint>
	<link 				name = "spine2_limb">
		<inertial>
			<origin 	rpy = "0.0 0.0 0.0" xyz = "0.0 0.05 0.0" />
			<mass 		value = "8.94" />
			<inertia 	ixx = "0.1" ixy = "0.0" ixz = "0.0" iyy = "0.1" iyz = "0.0" izz = "0.1" />
		</inertial>
		<visual>
			<origin 	rpy = "0.0 1.57 0.0" xyz = "0.0 0.05 0.0" />
			<geometry>
				<cylinder length = "0.22" radius = "0.06" />
			</geometry>
        	<material 	name="Purple">
          		<color 	rgba="0.5 0.0 0.5 1.0"/>
        	</material>
      	</visual>
		<collision>
			<origin 	rpy = "0.0 1.57 0.0" xyz = "0.0 0.05 0.0" />
			<geometry>
				<cylinder length = "0.22" radius = "0.06" />
			</geometry>
		</collision>
	</link>

    *** neck ***
	<joint 				name = "neck_rz" type = "revolute">
		<parent 		link = "spine2_limb" />
		<child 			link = "neck_rz" />
		<limit 			effort = "100.0" velocity= "0.5" lower = "-0.2" upper = "0.2" />
		<origin 		rpy = "0.0 0.0 0.0" xyz = "0.0 0.2485 0.0"  />
		<axis 			xyz = "0.0 0.0 1.0" />
	</joint>
	<link 				name = "neck_rz">
		<inertial>
			<origin 	rpy = "0.0 0.0 0.0" xyz = "0.0 0.0 0.0" />
			<mass 		value = "1e-05" />
			<inertia 	ixx = "0.1" ixy = "0.0" ixz = "0.0" iyy = "0.1" iyz = "0.0" izz = "0.1" />
		</inertial>
		<collision>
			<origin 	rpy = "0.0 1.57 0.0" xyz = "0.0 0.0 0.0" />
			<geometry>
				<cylinder length = "0.22" radius = "0.04" />
			</geometry>
		</collision>
	</link>

	<joint 				name = "neck_rx" type = "revolute">
		<parent 		link = "neck_rz" />
		<child 			link = "neck_rx" />
		<limit 			effort = "100.0" velocity="0.5" lower= "-0.5" upper= "0.5" />
		<origin 		rpy = "0.0 0.0 0.0" xyz = "0.0 0.0 0.0"/>
		<axis 			xyz = "1.0 0.0 0.0" />
	</joint>
	<link 				name = "neck_rx">
		<inertial>
			<origin 	rpy = "0.0 0.0 0.0" xyz = "0.0 0.0 0.0" />
			<mass 		value =  "1e-06" />
			<inertia 	ixx = "0.1" ixy = "0.0" ixz = "0.0" iyy = "0.1" iyz = "0.0" izz = "0.1" />
		</inertial>
		<collision>
			<origin 	rpy = "0.0 1.57 0.0" xyz = "0.0 0.0 0.0" />
			<geometry>
				<cylinder length = "0.22" radius = "0.04" />
			</geometry>
		</collision>
	</link>
	
	<joint 				name = "neck_ry" type = "revolute">
		<parent 		link = "neck_rx" />
		<child 			link = "neck_ry" />
		<limit 			effort = "100.0" velocity=  "0.5" lower = "-0.2" upper = "0.2"  />
		<origin 		rpy = "0 0 0" xyz = "0.0 0.0 0.0"  />
		<axis 			xyz = "0.0 1.0 0.0" />
	</joint>
	<link 				name = "neck_ry">
		<inertial>
			<origin 	rpy = "0.0 0.0 0.0" xyz = "0.0 0.0 0.0" />
			<mass 		value = "1.0" />
			<inertia 	ixx = "0.1" ixy = "0.0" ixz = "0.0" iyy = "0.1" iyz = "0.0" izz = "0.1" />
		</inertial>
		<visual>
			<origin 	rpy = "0.0 1.57 0.0" xyz = "0.0 0.0 0.0" />
			<geometry>
				<cylinder length = "0.22" radius = "0.06" />
			</geometry>
        	<material 	name="Purple">
          		<color 	rgba="0.5 0.0 0.5 1.0"/>
        	</material>
      	</visual>
		<collision>
			<origin 	rpy = "0.0 1.57 0.0" xyz = "0.0 0.0 0.0" />
			<geometry>
				<cylinder length = "0.22" radius = "0.06" />
			</geometry>
		</collision>
	</link>

	*** Head ***
	<joint 				name = "head_rz" type = "revolute">
		<parent 		link = "neck_ry" />
		<child 			link = "head_rz" />
		<limit 			effort = "10.0" velocity= "0.5" lower= "-0.1" upper= "0.1" />
		<origin			rpy = "0.0 0.0 0.0" xyz ="0.0 0.0928 0.0"  />
		<axis 			xyz = "0.0 0.0 1.0" />
	</joint>
	<link 				name = "head_rz">
		<inertial>
			<origin 	rpy = "0.0 0.0 0.0" xyz = "0.0 0.0 0.0" />
			<mass 		value = "1" />
			<inertia 	ixx = "0.1" ixy = "0.0" ixz = "0.0" iyy = "0.1" iyz = "0.0" izz = "0.1" />
		</inertial>
		<collision>
			<origin 	rpy = "1.57 0.0 0.0" xyz = "0.0 0.0 0.0" />
			<geometry>
				<cylinder length = "0.04" radius = "0.02" />
			</geometry>
		</collision>
	</link>

	<joint 				name = "head_rx" type = "revolute">
		<parent 		link = "head_rz" />
		<child 			link = "head_rx" />
		<limit 			effort = "10.0" velocity="0.5" lower= "-0.1" upper= "0.1" />
		<origin 		rpy = "0.0 0.0 0.0" xyz ="0.0 0.0 0.0"/>
		<axis 			xyz = "1.0 0.0 0.0" />
	</joint>
	<link 				name = "head_rx">
		<inertial>
			<origin 	rpy = "0.0 0.0 0.0" xyz = "0.0 0.0 0.0" />
			<mass 		value = "1e-05" />
			<inertia 	ixx = "0.1" ixy = "0" ixz = "0" iyy = "0.1" iyz = "0" izz = "0.1" />
		</inertial>
		<collision>
			<origin 	rpy = "1.57 0.0 0.0" xyz = "0.0 0.0 0.0" />
			<geometry>
				<cylinder length = "0.04" radius = "0.02" />
			</geometry>
		</collision>
	</link>
	
	<joint 				name = "head_ry" type = "revolute">
		<parent 		link = "head_rx" />
		<child 			link = "head_ry" />
		<limit 			effort = "10.0" lower= "-0.2" upper= "0.2" velocity=  "0.5" />
		<origin 		rpy = "0.0 0.0 0.0" xyz = "0.0 0.0 0.0"  />
		<axis 			xyz = "0.0 1.0 0.0" />
	</joint>
	<link 				name = "head_ry">
		<inertial>
			<origin 	rpy = "0.0 0.0 0.0" xyz = "0.0 0.0 0.0" />
			<mass 		value = "1e-05" />
			<inertia 	ixx = "0.1" ixy = "0.0" ixz = "0.0" iyy = "0.1" iyz = "0.0" izz = "0.1" />
		</inertial>
		<collision>
			<origin 	rpy = "1.57 0.0 0.0" xyz = "0.0 0.0 0.0" />
			<geometry>
				<cylinder length = "0.04" radius = "0.02" />
			</geometry>
		</collision>
	</link>
	
	*** Top ***
	<joint 				name = "top" type = "fixed">
		<parent 		link = "head_ry" />
		<child 			link = "top" />
		<origin 		rpy = "0.0 0.0 0.0" xyz = "0.0 0.1150 0.0" />
	</joint>
	<link 				name = "top">
		<inertial>
			<origin 	rpy = "0.0 0.0 0.0" xyz = "0.0 0.0 0.0" />
			<mass 		value = "5.64" />
			<inertia 	ixx = "0.1" ixy = "0.0" ixz = "0.0" iyy = "0.1" iyz = "0.0" izz = "0.1" />
		</inertial>
		<visual>
			<origin 	rpy = "0.0 0.0 0.0" xyz = "0.0 0.0 0.0" />
			<geometry>
				<sphere radius = "0.08" />
			</geometry>
        	<material 	name="Purple">
          		<color 	rgba="0.5 0.0 0.5 1.0"/>
        	</material>
      	</visual>
		<collision>
			<origin 	rpy = "0.0 0.0 0.0" xyz = "0.0 0.0 0.0" />
			<geometry>
				<sphere radius = "0.08" />
			</geometry>
		</collision>
	</link>

	*** left collar ***
	<joint 				name = "L_Collar_rz" type = "revolute">
		<parent 		link = "spine2_limb" />
		<child 			link = "L_Collar_rz" />
		<limit	 		effort = "1000.0" velocity = "0.5" lower = "-0.1" upper = "0.1" />
		<origin 		rpy = "0.0 0.0 0.0" xyz = "0.0 0.2485 0.0"  />
		<axis 			xyz = "0.0 0.0 1.0" />
	</joint>
	<link 				name = "L_Collar_rz">
		<inertial>
			<origin 	rpy = "0.0 0.0 0.0" xyz = "0.05 0.0 0.0" />
			<mass 		value = "1e-05" />
			<inertia 	ixx = "0.1" ixy = "0.0" ixz = "0.0" iyy = "0.1" iyz = "0.0" izz = "0.1" />
		</inertial>
		<collision>
			<origin 	rpy = "0.0 0.0 0.0" xyz = "0.05 0.0 0.0" />
			<geometry>
				<sphere radius = "0.01" />
			</geometry>
		</collision>
	</link>

	<joint 				name = "L_Collar_rx" type = "revolute">
		<parent 		link = "L_Collar_rz" />
		<child 			link = "L_Collar_rx" />
		<limit 			effort = "1000.0" velocity = "0.5" lower = "-0.1" upper = "0.1" />
		<origin 		rpy = "0.0 0.0 0.0" xyz = "0.0 0.0 0.0"/>
		<axis			xyz = "1.0 0.0 0.0" />
	</joint>
	<link 				name = "L_Collar_rx">
		<inertial>
			<origin 	rpy = "0.0 0.0 0.0" xyz = "0.05 0.0 0.0" />
			<mass 		value = "1e-05" />
			<inertia 	ixx = "0.1" ixy = "0.0" ixz = "0.0" iyy = "0.1" iyz = "0.0" izz = "0.1" />
		</inertial>
		<collision>
			<origin 	rpy = "0.0 0.0 0.0" xyz = "0.05 0.0 0.0" />
			<geometry>
				<sphere radius = "0.01" />
			</geometry>
		</collision>
	</link>
	
	<joint 				name = "L_Collar_ry" type = "revolute">
		<parent 		link = "L_Collar_rx" />
		<child 			link = "L_Collar_ry" />
		<limit 			effort = "1000.0" velocity = "0.5" lower = "-0.1" upper= "0.1" />
		<origin 		rpy = "0.0 0.0 0.0" xyz = "0.0 0.0 0.0"  />
		<axis 			xyz = "0.0 1.0 0.0" />
	</joint>
	<link 				name = "L_Collar_ry">
		<inertial>
			<origin 	rpy = "0.0 0.0 0.0" xyz = "0.05 0.0 0.0" />
			<mass 		value = "1e-05" />
			<inertia 	ixx = "0.1" ixy = "0.0" ixz = "0.0" iyy = "0.1" iyz = "0.0" izz = "0.1" />
		</inertial>
		<collision>
			<origin 	rpy = "0.0 0.0 0.0" xyz = "0.05 0.0 0.0" />
			<geometry>
				<sphere radius = "0.01" />
			</geometry>
		</collision>
	</link>

	<joint 				name = "L_Collar_limb" type = "fixed">
		<parent 		link = "L_Collar_ry" />
		<child 			link = "L_Collar_limb" />
		<origin 		rpy = "0.0 0.0 0.0" xyz = "0.0 0.0 0.0"  />
	</joint>
	<link				name = "L_Collar_limb">
		<inertial>
			<origin 	rpy = "0.0 0.0 0.0" xyz = "0.05 0.0 0.0" />
			<mass 		value = "6.89" />
			<inertia 	ixx = "0.1" ixy = "0.0" ixz = "0.0" iyy = "0.1" iyz = "0.0" izz = "0.1" />
		</inertial>
		<visual>
			<origin 	rpy = "0.0 0.0 0.0"  xyz = "0.05 0.0 0.0" />
			<geometry>
				<sphere radius = "0.06" />
			</geometry>
        	<material 	name="Purple">
          		<color 	rgba="0.5 0.0 0.5 1.0"/>
        	</material>
      	</visual>
		<collision>
			<origin 	rpy = "0.0 0.0 0.0"  xyz = "0.05 0.0 0.0" />
			<geometry>
				<sphere radius = "0.06" />
			</geometry>
		</collision>
	</link>
	
	*** left shoulder ***
	<joint 				name = "L_Shoulder_rz" type = "revolute">
		<parent 		link = "L_Collar_limb" />
		<child 			link = "L_Shoulder_rz" />
		<limit 			effort = "1000.0" velocity = "0.5" lower= "-0.3" upper= "0.3" />
		<origin 		rpy = "0.0 0.0 0.0" xyz = "0.1249 0.0 0.0"  />
		<axis 			xyz = "0.0 0.0 1.0" />
	</joint>
	<link 				name = "L_Shoulder_rz">
		<inertial>
			<origin 	rpy = "0.0 0.0 0.0" xyz = "0.0 0.0 0.0" />
			<mass 		value = "1e-05" />
			<inertia 	ixx = "0.1" ixy = "0.0" ixz = "0.0" iyy = "0.1" iyz = "0.0" izz = "0.1" />
		</inertial>
		<visual>
			<origin 	rpy = "0 0 0" xyz = "0.0 0.0 0.0" />
			<geometry>
				<sphere radius = "0.04" />
			</geometry>
        	<material 	name="Yellow">
          		<color 	rgba="0.5 0.5 0.0 1.0"/>
        	</material>
      	</visual>
		<collision>
			<origin 	rpy = "0.0 0.0 0.0" xyz = "0.0 0.0 0.0" />
			<geometry>
				<sphere radius = "0.04" />
			</geometry>
		</collision>
	</link>

	<joint 				name = "L_Shoulder_rx" type = "revolute">
		<parent 		link = "L_Shoulder_rz" />
		<child 			link = "L_Shoulder_rx" />
		<limit 			effort = "1000.0" velocity = "0.5" lower= "-1.6" upper= "1.8" />
		<origin 		rpy = "0.0 0.0 0.0" xyz = "0.0 0.0 0.0"/>
		<axis 			xyz = "1.0 0.0 0.0" />
	</joint>
	<link 				name = "L_Shoulder_rx">
		<inertial>
			<origin 	rpy = "0.0 0.0 0.0" xyz = "0.0 0.0 0.0" />
			<mass 		value = "1e-05" />
			<inertia 	ixx = "0.1" ixy = "0.0" ixz = "0.0" iyy = "0.1" iyz = "0.0" izz = "0.1" />
		</inertial>
		<collision>
			<origin 	rpy = "0.0 0.0 0.0" xyz = "0.0 0.0 0.0" />
			<geometry>
				<sphere radius = "0.04" />
			</geometry>
		</collision>
	</link>
	
	<joint 				name = "L_Shoulder_ry" type = "revolute">
		<parent 		link = "L_Shoulder_rx" />
		<child 			link = "L_Shoulder_ry" />
		<limit 			effort = "1000.0" velocity = "0.5" lower= "-2.0" upper= "2.0" />
		<origin 		rpy = "0.0 0.0 0.0" xyz = "0.0 0.0 0.0" />
		<axis 			xyz = "0.0 1.0 0.0" />
	</joint>
	<link 				name = "L_Shoulder_ry">
		<inertial>
			<origin 	rpy = "0.0 0.0 0.0" xyz = "0.0 0.0 0.0" />
			<mass 		value = "1e-05" />
			<inertia 	ixx = "0.1" ixy = "0.0" ixz = "0.0" iyy = "0.1" iyz = "0.0" izz = "0.1" />
		</inertial>
		<collision>
			<origin 	rpy = "0.0 0.0 0.0" xyz = "0.0 0.0 0.0" />
			<geometry>
				<sphere radius = "0.04" />
			</geometry>
		</collision>
	</link>

	<joint 				name = "L_Shoulder_limb" type = "fixed">
		<parent 		link = "L_Shoulder_ry" />
		<child 			link = "L_Shoulder_limb" />
		<origin 		rpy = "0 0 0" xyz = "0.0 0.0 0.0" />
	</joint>
	<link 				name = "L_Shoulder_limb">
		<inertial>
			<origin 	rpy = "0.0 0.0 0.0" xyz = "0.12 0.0 0.0" />
			<mass 		value = "2.22" />
			<inertia 	ixx = "0.1" ixy = "0.0" ixz = "0.0" iyy = "0.1" iyz = "0.0" izz = "0.1" />
		</inertial>
		<visual>
			<origin 	rpy = "0.0 1.57 0.0"  xyz = "0.13 0.0 0.0" />
			<geometry>
				<cylinder length = "0.21" radius = "0.04"/>
			</geometry>
        	<material 	name="Purple">
          		<color 	rgba="0.5 0.0 0.5 1.0"/>
        	</material>
      	</visual>
		<collision>
			<origin 	rpy = "0.0 1.57 0.0"  xyz = "0.13 0.0 0.0" />
			<geometry>
				<cylinder length = "0.21" radius = "0.04"/>
			</geometry>
		</collision>
	</link>
	
	*** left elbow ***
    <joint 				name = "L_Elbow_rz" type = "revolute">
		<parent 		link = "L_Shoulder_limb" />
		<child 			link = "L_Elbow_rz" />
		<limit 			effort = "1000.0" velocity = "0.5" lower = "-0.001" upper = "0.001" />
		<origin 		rpy = "0.0 0.0 0.0" xyz = "0.2598 0.0 0.0"/>
		<axis 			xyz = "0.0 0.0 1.0" />
	</joint>
	<link 				name = "L_Elbow_rz">
		<inertial>
			<origin 	rpy = "0.0 0.0 0.0" xyz = "0.0 0.0 0.0" />
			<mass 		value = "1e-05" />
			<inertia 	ixx = "0.1" ixy = "0.0" ixz = "0.0" iyy = "0.1" iyz = "0.0" izz = "0.1" />
		</inertial>
		<visual>
			<origin 	rpy = "0 0 0" xyz = "0.0 0.0 0.0" />
			<geometry>
				<sphere radius = "0.04" />
			</geometry>
        	<material 	name="Yellow">
          		<color 	rgba="0.5 0.5 0.0 1.0"/>
        	</material>
      	</visual>
		<collision>
			<origin 	rpy = "0.0 0.0 0.0" xyz = "0.0 0.0 0.0" />
			<geometry>
				<sphere radius = "0.04" />
			</geometry>
		</collision>
	</link>

    <joint 				name = "L_Elbow_rx" type = "revolute">
		<parent 		link = "L_Elbow_rz" />
		<child 			link = "L_Elbow_rx" />
		<limit 			effort = "1000.0" velocity = "0.5" lower = "-0.001" upper = "0.001" />
		<origin 		rpy = "0.0 0.0 0.0" xyz = "0.0 0.0 0.0"/>
		<axis 			xyz = "1.0 0.0 0.0" />
	</joint>
	<link 				name = "L_Elbow_rx">
		<inertial>
			<origin 	rpy = "0.0 0.0 0.0" xyz = "0.0 0.0 0.0" />
			<mass 		value = "1e-05" />
			<inertia 	ixx = "0.1" ixy = "0.0" ixz = "0.0" iyy = "0.1" iyz = "0.0" izz = "0.1" />
		</inertial>
		<collision>
			<origin 	rpy = "0.0 0.0 0.0" xyz = "0.0 0.0 0.0" />
			<geometry>
				<sphere radius = "0.04" />
			</geometry>
		</collision>
	</link>

	<joint 				name = "L_Elbow_ry" type = "revolute">
		<parent 		link = "L_Elbow_rx" />
		<child 			link = "L_Elbow_ry" />
		<limit 			effort = "1000.0" velocity="0.5" lower = "-1.5" upper = "0.0" />
		<origin 		rpy = "0.0 0.0 0.0" xyz = "0.0 0.0 0.0"/>
		<axis 			xyz = "0.0 1.0 0.0" />
	</joint>
	<link 				name = "L_Elbow_ry">
		<inertial>
			<origin 	rpy = "0.0 0.0 0.0" xyz = "0.0 0.0 0.0" />
			<mass 		value = "1e-05" />
			<inertia 	ixx = "0.1" ixy = "0.0" ixz = "0.0" iyy = "0.1" iyz = "0.0" izz = "0.1" />
		</inertial>
		<collision>
			<origin 	rpy = "0.0 0.0 0.0" xyz = "0.0 0.0 0.0" />
			<geometry>
				<sphere radius = "0.04" />
			</geometry>
		</collision>
	</link>

	<joint 				name = "L_Elbow_limb" type = "fixed">
		<parent 		link = "L_Elbow_ry" />
		<child 			link = "L_Elbow_limb" />
		<origin 		rpy = "0.0 0.0 0.0" xyz = "0.0 0.0 0.0"  />
	</joint>
	<link 				name = "L_Elbow_limb">
		<inertial>
			<origin 	rpy = "0.0 0.0 0.0" xyz = "0.11 0.0 0.0" />
			<mass 		value = "1.27" />
			<inertia 	ixx = "0.1" ixy = "0.0" ixz = "0.0" iyy = "0.1" iyz = "0.0" izz = "0.1" />
		</inertial>
		<visual>
			<origin 	rpy = "0 1.57 0" xyz = "0.12 0.0 0.0" />
			<geometry>
				<cylinder length = "0.21" radius = "0.04"/>
			</geometry>
        	<material 	name="Purple">
          		<color 	rgba="0.5 0.0 0.5 1.0"/>
        	</material>
      	</visual>
		<collision>
			<origin 	rpy = "0 1.57 0" xyz = "0.12 0.0 0.0" />
			<geometry>
				<cylinder length = "0.21" radius = "0.04"/>
			</geometry>
		</collision>
	</link>
	
	*** left wrist ***
	<joint 				name = "L_Wrist_rz" type = "revolute">
		<parent 		link = "L_Elbow_limb" />
		<child 			link = "L_Wrist_rz" />
		<limit 			effort = "1000.0" velocity = "0.5" lower = "-0.01" upper = "0.01" />
		<origin 		rpy = "0.0 0.0 0.0" xyz = "0.2455 0.0 0.0"  />
		<axis 			xyz = "0.0 0.0 1.0" />
	</joint>
	<link 				name = "L_Wrist_rz">
		<inertial>
			<origin 	rpy = "0.0 0.0 0.0" xyz = "0.0 0.0 0.0" />
			<mass 		value = "1e-05" />
			<inertia 	ixx = "0.1" ixy = "0.0" ixz = "0.0" iyy = "0.1" iyz = "0.0" izz = "0.1" />
		</inertial>
		<collision>
			<origin 	rpy = "0.0 0.0 0.0"  xyz = "0.0 0.0 0.0" />
			<geometry>
				<sphere radius = "0.03" />
			</geometry>
		</collision>
	</link>

	<joint 				name = "L_Wrist_rx" type = "revolute">
		<parent 		link = "L_Wrist_rz" />
		<child 			link = "L_Wrist_rx" />
		<limit 			effort = "1000.0" velocity = "0.5" lower = "-0.01" upper = "0.01" />
		<origin 		rpy = "0.0 0.0 0.0" xyz = "0.0 0.0 0.0"/>
		<axis 			xyz = "1.0 0.0 0.0" />
	</joint>
	<link 				name = "L_Wrist_rx">
		<inertial>
			<origin 	rpy = "0.0 0.0 0.0" xyz = "0.0 0.0 0.0" />
			<mass 		value = "1e-05" />
			<inertia 	ixx = "0.1" ixy = "0.0" ixz = "0.0" iyy = "0.1" iyz = "0.0" izz = "0.1" />
		</inertial>
		<collision>
			<origin 	rpy = "0.0 0.0 0.0" xyz = "0.0 0.0 0.0" />
			<geometry>
				<sphere radius = "0.03" />
			</geometry>
		</collision>
	</link>
	
	<joint 				name = "L_Wrist_ry" type = "revolute">
		<parent 		link = "L_Wrist_rx" />
		<child 			link = "L_Wrist_ry" />
		<limit 			effort = "1000.0" velocity = "0.5" lower = "-0.01" upper = "0.01" />
		<origin 		rpy = "0.0 0.0 0.0" xyz = "0.0 0.0 0.0"  />
		<axis 			xyz = "0.0 1.0 0.0" />
	</joint>
	<link 				name = "L_Wrist_ry">
		<inertial>
			<origin 	rpy = "0.0 0.0 0.0" xyz = "0.0 0.0 0.0" />
			<mass 		value = "1e-05" />
			<inertia 	ixx = "0.1" ixy = "0.0" ixz = "0.0" iyy = "0.1" iyz = "0.0" izz = "0.1" />
		</inertial>
		<collision>
			<origin 	rpy = "0.0 0.0 0.0" xyz = "0.0 0.0 0.0" />
			<geometry>
				<sphere radius = "0.03" />
			</geometry>
		</collision>
	</link>

    *** left hand end***
	<joint 				name = "L_Hend" type = "fixed">
		<parent 		link = "L_Wrist_ry" />
		<child 			link = "L_Hend" />
		<origin 		rpy = "0.0 0.0 0.0" xyz = "0.075 0.0 0.0"  />
	</joint>
	<link 				name = "L_Hend">
		<inertial>
			<origin 	rpy = "0.0 0.0 0.0" xyz = "0.0 0.0 0.0" />
			<mass 		value = "0.01" />
			<inertia 	ixx = "0.1" ixy = "0.0" ixz = "0.0" iyy = "0.1" iyz = "0.0" izz = "0.1" />
		</inertial>
		<collision>
			<origin 	rpy = "0.0 0.0 0.0" xyz = "0.0 0.0 0.0" />
			<geometry>
				<box 	size = "0.08 0.08 0.08" />
			</geometry>
		</collision>
	</link>
	
	*** right collar ***
	<joint 				name = "R_Collar_rz" type = "revolute">
		<parent 		link = "spine2_limb" />
		<child 			link = "R_Collar_rz" />
		<limit 			effort = "1000.0" velocity="0.5" lower = "-0.1" upper = "0.1" />
		<origin 		rpy = "0.0 0.0 0.0" xyz = "0.0 0.2485 0.0"  />
		<axis 			xyz = "0.0 0.0 1.0" />
	</joint>
	<link 				name = "R_Collar_rz">
		<inertial>
			<origin 	rpy = "0.0 0.0 0.0" xyz = "-0.05 0.0 0.0" />
			<mass 		value = "1e-05" />
			<inertia 	ixx = "0.1" ixy = "0.0" ixz = "0.0" iyy = "0.1" iyz = "0.0" izz = "0.1" />
		</inertial>
		<collision>
			<origin 	rpy = "0.0 0.0 0.0" xyz = "-0.05 0.0 0.0" />
			<geometry>
				<sphere radius = "0.01" />
			</geometry>
		</collision>
	</link>

	<joint 				name = "R_Collar_rx" type = "revolute">
		<parent 		link = "R_Collar_rz" />
		<child 			link = "R_Collar_rx" />
		<limit 			effort = "1000.0" velocity="0.5" lower = "-0.1" upper = "0.1" />
		<origin 		rpy = "0.0 0.0 0.0" xyz = "0.0 0.0 0.0"/>
		<axis 			xyz = "1.0 0.0 0.0" />
	</joint>
	<link 				name = "R_Collar_rx">
		<inertial>
			<origin 	rpy = "0.0 0.0 0.0" xyz = "-0.05 0.0 0.0" />
			<mass 		value = "1e-05" />
			<inertia 	ixx = "0.1" ixy = "0.0" ixz = "0.0" iyy = "0.1" iyz = "0.0" izz = "0.1" />
		</inertial>
		<collision>
			<origin 	rpy = "0.0 0.0 0.0" xyz = "-0.05 0.0 0.0" />
			<geometry>
				<sphere radius = "0.01" />
			</geometry>
		</collision>
	</link>
	
	<joint 				name = "R_Collar_ry" type = "revolute">
		<parent 		link = "R_Collar_rx" />
		<child 			link = "R_Collar_ry" />
		<limit 			effort = "1000.0" velocity="0.5" lower = "-0.1" upper = "0.1" />
		<origin 		rpy = "0.0 0.0 0.0" xyz = "0.0 0.0 0.0" />
		<axis 			xyz = "0.0 1.0 0.0" />
	</joint>
	<link 				name = "R_Collar_ry">
		<inertial>
			<origin 	rpy = "0.0 0.0 0.0" xyz = "-0.05 0.0 0.0" />
			<mass 		value =  "1e-06" />
			<inertia 	ixx = "0.1" ixy = "0.0" ixz = "0.0" iyy = "0.1" iyz = "0.0" izz = "0.1" />
		</inertial>
		<collision>
			<origin 	rpy = "0.0 0.0 0.0" xyz = "-0.05 0.0 0.0" />
			<geometry>
				<sphere radius = "0.01" />
			</geometry>
		</collision>
	</link>

	<joint 				name = "R_Collar_limb" type = "fixed">
		<parent 		link = "R_Collar_ry" />
		<child 			link = "R_Collar_limb" />
		<origin 		rpy = "0.0 0.0 0.0" xyz = "0.0 0.0 0.0"  />
	</joint>
	<link 				name = "R_Collar_limb">
		<inertial>
			<origin 	rpy = "0.0 0.0 0.0" xyz = "-0.05 0.0 0.0" />
			<mass 		value = "6.89" />
			<inertia 	ixx = "0.1" ixy = "0.0" ixz = "0.0" iyy = "0.1" iyz = "0.0" izz = "0.1" />
		</inertial>
		<visual>
			<origin 	rpy = "0.0 0.0 0.0"  xyz = "-0.05 0.0 0.0" />
			<geometry>
				<sphere radius = "0.06" />
			</geometry>
        	<material 	name="Purple">
          		<color 	rgba="0.5 0.0 0.5 1.0"/>
        	</material>
      	</visual>
		<collision>
			<origin 	rpy = "0.0 0.0 0.0" xyz = "-0.05 0.0 0.0" />
			<geometry>
				<sphere radius = "0.06" />
			</geometry>
		</collision>
	</link>
	
	*** right shoulder ***
	<joint 				name = "R_Shoulder_rz" type = "revolute">
		<parent 		link = "R_Collar_limb" />
		<child 			link = "R_Shoulder_rz" />
		<limit 			effort = "1000.0" velocity = "0.5" lower= "-0.3" upper= "0.3" />
		<origin 		rpy = "0.0 0.0 0.0" xyz = "-0.1249 0.0 0.0"  />
		<axis 			xyz = "0.0 0.0 1.0" />
	</joint>
	<link 				name = "R_Shoulder_rz">
		<inertial>
			<origin 	rpy = "0.0 0.0 0.0" xyz = "0.0 0.0 0.0" />
			<mass 		value = "1e-05" />
			<inertia 	ixx = "0.1" ixy = "0.0" ixz = "0.0" iyy = "0.1" iyz = "0.0" izz = "0.1" />
		</inertial>
		<visual>
			<origin 	rpy = "0 0 0" xyz = "0.0 0.0 0.0" />
			<geometry>
				<sphere radius = "0.04" />
			</geometry>
        	<material 	name="Yellow">
          		<color 	rgba="0.5 0.5 0.0 1.0"/>
        	</material>
      	</visual>
		<collision>
			<origin 	rpy = "0.0 0.0 0.0" xyz = "0.0 0.0 0.0" />
			<geometry>
				<sphere radius = "0.04" />
			</geometry>
		</collision>
	</link>

	<joint 				name = "R_Shoulder_rx" type = "revolute">
		<parent 		link = "R_Shoulder_rz" />
		<child 			link = "R_Shoulder_rx" />
		<limit 			effort = "1000.0" velocity = "0.5" lower= "-1.6" upper= "1.8" />
		<origin 		rpy = "0.0 0.0 0.0" xyz = "0.0 0.0 0.0"/>
		<axis 			xyz = "1.0 0.0 0.0" />
	</joint>
	<link 				name = "R_Shoulder_rx">
		<inertial>
			<origin 	rpy = "0.0 0.0 0.0" xyz = "0.0 0.0 0.0" />
			<mass 		value = "1e-05" />
			<inertia 	ixx = "0.1" ixy = "0.0" ixz = "0.0" iyy = "0.1" iyz = "0.0" izz = "0.1" />
		</inertial>
		<collision>
			<origin 	rpy = "0.0 0.0 0.0" xyz = "0.0 0.0 0.0" />
			<geometry>
				<sphere radius = "0.04" />
			</geometry>
		</collision>
	</link>
	
	<joint 				name = "R_Shoulder_ry" type = "revolute">
		<parent 		link = "R_Shoulder_rx" />
		<child 			link = "R_Shoulder_ry" />
		<limit 			effort = "1000.0" velocity = "0.5" lower= "-2.0" upper= "2.0" />
		<origin 		rpy = "0.0 0.0 0.0" xyz = "0.0 0.0 0.0" />
		<axis 			xyz = "0.0 1.0 0.0" />
	</joint>
	<link 				name = "R_Shoulder_ry">
		<inertial>
			<origin 	rpy = "0.0 0.0 0.0" xyz = "0.0 0.0 0.0" />
			<mass 		value = "1e-05" />
			<inertia 	ixx = "0.1" ixy = "0.0" ixz = "0.0" iyy = "0.1" iyz = "0.0" izz = "0.1" />
		</inertial>
		<collision>
			<origin 	rpy = "0.0 0.0 0.0" xyz = "0.0 0.0 0.0" />
			<geometry>
				<sphere radius = "0.04" />
			</geometry>
		</collision>
	</link>

	<joint 				name = "R_Shoulder_limb" type = "fixed">
		<parent 		link = "R_Shoulder_ry" />
		<child 			link = "R_Shoulder_limb" />
		<origin 		rpy = "0 0 0" xyz = "0.0 0.0 0.0" />
	</joint>
	<link 				name = "R_Shoulder_limb">
		<inertial>
			<origin 	rpy = "0.0 0.0 0.0" xyz = "-0.13 0.0 0.0" />
			<mass 		value = "2.22" />
			<inertia 	ixx = "0.1" ixy = "0.0" ixz = "0.0" iyy = "0.1" iyz = "0.0" izz = "0.1" />
		</inertial>
		<visual>
			<origin 	rpy = "0.0 1.57 0.0"  xyz = "-0.13 0.0 0.0" />
			<geometry>
				<cylinder length = "0.21" radius = "0.04"/>
			</geometry>
        	<material 	name="Purple">
          		<color 	rgba="0.5 0.0 0.5 1.0"/>
        	</material>
      	</visual>
		<collision>
			<origin 	rpy = "0.0 1.57 0.0"  xyz = "-0.13 0.0 0.0" />
			<geometry>
				<cylinder length = "0.21" radius = "0.04"/>
			</geometry>
		</collision>
	</link>
	
	*** right elbow ***
	<joint 				name = "R_Elbow_rz" type = "revolute">
		<parent 		link = "R_Shoulder_limb" />
		<child 			link = "R_Elbow_rz" />
		<limit 			effort = "1000.0" velocity = "0.5" lower = "-0.001" upper = "0.001" />
		<origin 		rpy = "0.0 0.0 0.0" xyz = "-0.2598 0.0 0.0"/>
		<axis 			xyz = "0.0 0.0 1.0" />
	</joint>
	<link 				name = "R_Elbow_rz">
		<inertial>
			<origin 	rpy = "0.0 0.0 0.0" xyz = "0.0 0.0 0.0" />
			<mass 		value = "1e-05" />
			<inertia 	ixx = "0.1" ixy = "0.0" ixz = "0.0" iyy = "0.1" iyz = "0.0" izz = "0.1" />
		</inertial>
		<visual>
			<origin 	rpy = "0 0 0" xyz = "0.0 0.0 0.0" />
			<geometry>
				<sphere radius = "0.04" />
			</geometry>
        	<material 	name="Yellow">
          		<color 	rgba="0.5 0.5 0.0 1.0"/>
        	</material>
      	</visual>
		<collision>
			<origin 	rpy = "0.0 0.0 0.0" xyz = "0.0 0.0 0.0" />
			<geometry>
				<sphere radius = "0.04" />
			</geometry>
		</collision>
	</link>

    <joint 				name = "R_Elbow_rx" type = "revolute">
		<parent 		link = "R_Elbow_rz" />
		<child 			link = "R_Elbow_rx" />
		<limit 			effort = "1000.0" velocity = "0.5" lower = "-0.001" upper = "0.001" />
		<origin 		rpy = "0.0 0.0 0.0" xyz = "0.0 0.0 0.0"/>
		<axis 			xyz = "1.0 0.0 0.0" />
	</joint>
	<link 				name = "R_Elbow_rx">
		<inertial>
			<origin 	rpy = "0.0 0.0 0.0" xyz = "0.0 0.0 0.0" />
			<mass 		value = "1e-05" />
			<inertia 	ixx = "0.1" ixy = "0.0" ixz = "0.0" iyy = "0.1" iyz = "0.0" izz = "0.1" />
		</inertial>
		<collision>
			<origin 	rpy = "0.0 0.0 0.0" xyz = "0.0 0.0 0.0" />
			<geometry>
				<sphere radius = "0.04" />
			</geometry>
		</collision>
	</link>

	<joint 				name = "R_Elbow_ry" type = "revolute">
		<parent 		link = "R_Elbow_rx" />
		<child 			link = "R_Elbow_ry" />
		<limit 			effort = "1000.0" velocity="0.5" lower = "0.0" upper = "1.5" />
		<origin 		rpy = "0.0 0.0 0.0" xyz = "0.0 0.0 0.0"/>
		<axis 			xyz = "0.0 1.0 0.0" />
	</joint>
	<link 				name = "R_Elbow_ry">
		<inertial>
			<origin 	rpy = "0.0 0.0 0.0" xyz = "0.0 0.0 0.0" />
			<mass 		value = "1e-05" />
			<inertia 	ixx = "0.1" ixy = "0.0" ixz = "0.0" iyy = "0.1" iyz = "0.0" izz = "0.1" />
		</inertial>
		<collision>
			<origin 	rpy = "0.0 0.0 0.0" xyz = "0.0 0.0 0.0" />
			<geometry>
				<sphere radius = "0.04" />
			</geometry>
		</collision>
	</link>

	<joint 				name = "R_Elbow_limb" type = "fixed">
		<parent 		link = "R_Elbow_ry" />
		<child 			link = "R_Elbow_limb" />
		<origin 		rpy = "0.0 0.0 0.0" xyz = "0.0 0.0 0.0"  />
	</joint>
	<link 				name = "R_Elbow_limb">
		<inertial>
			<origin 	rpy = "0.0 0.0 0.0" xyz = "-0.11 0.0 0.0" />
			<mass 		value = "1.27" />
			<inertia 	ixx = "0.1" ixy = "0.0" ixz = "0.0" iyy = "0.1" iyz = "0.0" izz = "0.1" />
		</inertial>
		<visual>
			<origin 	rpy = "0 1.57 0" xyz = "-0.12 0.0 0.0" />
			<geometry>
				<cylinder length = "0.21" radius = "0.04"/>
			</geometry>
        	<material 	name="Purple">
          		<color 	rgba="0.5 0.0 0.5 1.0"/>
        	</material>
      	</visual>
		<collision>
			<origin 	rpy = "0 1.57 0" xyz = "-0.12 0.0 0.0" />
			<geometry>
				<cylinder length = "0.21" radius = "0.04"/>
			</geometry>
		</collision>
	</link>
	
	*** right wrist ***
	<joint 				name = "R_Wrist_rz" type = "revolute">
		<parent 		link = "R_Elbow_limb" />
		<child 			link = "R_Wrist_rz" />
		<limit 			effort = "1000.0" velocity = "0.5" lower = "-0.01" upper = "0.01" />
		<origin 		rpy = "0.0 0.0 0.0" xyz = "-0.2455 0.0 0.0"  />
		<axis 			xyz = "0.0 0.0 1.0" />
	</joint>
	<link 				name = "R_Wrist_rz">
		<inertial>
			<origin 	rpy = "0.0 0.0 0.0" xyz = "0.0 0.0 0.0" />
			<mass 		value = "1e-05" />
			<inertia 	ixx = "0.1" ixy = "0.0" ixz = "0.0" iyy = "0.1" iyz = "0.0" izz = "0.1" />
		</inertial>
		<collision>
			<origin 	rpy = "0.0 0.0 0.0"  xyz = "0.0 0.0 0.0" />
			<geometry>
				<sphere radius = "0.03" />
			</geometry>
		</collision>
	</link>

	<joint 				name = "R_Wrist_rx" type = "revolute">
		<parent 		link = "R_Wrist_rz" />
		<child 			link = "R_Wrist_rx" />
		<limit 			effort = "1000.0" velocity = "0.5" lower = "-0.01" upper = "0.01" />
		<origin 		rpy = "0.0 0.0 0.0" xyz = "0.0 0.0 0.0"/>
		<axis 			xyz = "1.0 0.0 0.0" />
	</joint>
	<link 				name = "R_Wrist_rx">
		<inertial>
			<origin 	rpy = "0.0 0.0 0.0" xyz = "0.0 0.0 0.0" />
			<mass 		value = "1e-05" />
			<inertia 	ixx = "0.1" ixy = "0.0" ixz = "0.0" iyy = "0.1" iyz = "0.0" izz = "0.1" />
		</inertial>
		<collision>
			<origin 	rpy = "0.0 0.0 0.0" xyz = "0.0 0.0 0.0" />
			<geometry>
				<sphere radius = "0.03" />
			</geometry>
		</collision>
	</link>
	
	<joint 				name = "R_Wrist_ry" type = "revolute">
		<parent 		link = "R_Wrist_rx" />
		<child 			link = "R_Wrist_ry" />
		<limit 			effort = "1000.0" velocity = "0.5" lower = "-0.01" upper = "0.01" />
		<origin 		rpy = "0.0 0.0 0.0" xyz = "0.0 0.0 0.0"  />
		<axis 			xyz = "0.0 1.0 0.0" />
	</joint>
	<link 				name = "R_Wrist_ry">
		<inertial>
			<origin 	rpy = "0.0 0.0 0.0" xyz = "0.0 0.0 0.0" />
			<mass 		value = "1e-05" />
			<inertia 	ixx = "0.1" ixy = "0.0" ixz = "0.0" iyy = "0.1" iyz = "0.0" izz = "0.1" />
		</inertial>
		<collision>
			<origin 	rpy = "0.0 0.0 0.0" xyz = "0.0 0.0 0.0" />
			<geometry>
				<sphere radius = "0.03" />
			</geometry>
		</collision>
	</link>

    *** right hand end***
	<joint 				name = "R_Hend" type = "fixed">
		<parent 		link = "R_Wrist_ry" />
		<child 			link = "R_Hend" />
		<origin 		rpy = "0.0 0.0 0.0" xyz = "-0.075 0.0 0.0"  />
	</joint>
	<link 				name = "R_Hend">
		<inertial>
			<origin 	rpy = "0.0 0.0 0.0" xyz = "0.0 0.0 0.0" />
			<mass 		value = "0.01" />
			<inertia 	ixx = "0.1" ixy = "0.0" ixz = "0.0" iyy = "0.1" iyz = "0.0" izz = "0.1" />
		</inertial>
		<collision>
			<origin 	rpy = "0.0 0.0 0.0" xyz = "0.0 0.0 0.0" />
			<geometry>
				<box 	size = "0.08 0.08 0.08" />
			</geometry>
		</collision>
	</link>

</robot>